Workbook
Name AbaInstanciaSW: PARAMETROS!$E$19
Name ParecerFinalAuditoria: PARAMETROS!$G$31:$G$33
Name NivelSolicitado: DADOS_AVAL!$B$10
Name ItensResultadoAvaliacaoInicial: PARAMETROS!$D$38:$D$47
Name AbaInstanciaSV: PARAMETROS!$E$20
Name ReferenciaInstanciaSW: PARAMETROS!$G$13
Name TipoClienteOperacaoInstancia: PARAMETROS!$G$19:$G$27
Name SituacoesInstanciasSV: PARAMETROS!$A$88:$A$93
Name InstanciaEquipeSV: PARAMETROS!$J$14
Name CidadeUnidadeOrganizacional: DADOS_EMPRESA!$B$5
Name StatusInstanciasSV: PARAMETROS!$I$14
Name VariacoesNaoSeAplica: PARAMETROS!$H$3:$H$9
Name EnderecoUO3: DADOS_EMPRESA!$B$16
Name DadosProjetos: PROJETOS!$A$5:$N$35
Name FasesServicos: PARAMETROS!$H$19:$H$27
Name ExclusoesModeloSelecionado: PARAMETROS!$D$143:$D$145
Name FasesProjetos: PARAMETROS!$F$19:$F$27
Name PapelEquipeSV: PARAMETROS!$K$14
Name SituacoesInstanciasRH: PARAMETROS!$A$96:$A$101
Name ModeloSV: PARAMETROS!$C$67:$D$79
Name AssociacaoAgenteSOFTEX: PARAMETROS!$A$41:$A$42
Name ProcessosModeloSV: PARAMETROS!$D$67:$D$78
Name GestorInstanciasSV: PARAMETROS!$H$14
Name ExclusoesModeloRH: PARAMETROS!$C$137:$D$139
Name NomesProjetos: PROJETOS!$A$5:$A$35
Name FaixaReceitaOperacional: PARAMETROS!$A$28:$A$32
Name SiglasUF: PARAMETROS!$A$49:$A$75
Name NomesInstanciasSelecionadas: PARAMETROS!$F$125:$F$177
Name ImportanciaOrganizacao: PARAMETROS!$I$19:$I$27
Name SituacoesInstanciasSW: PARAMETROS!$A$78:$A$85
Name LocalUO1: DADOS_EMPRESA!$B$8
Name PapelEquipeSW: PARAMETROS!$K$13
Name GestorInstanciasSW: PARAMETROS!$H$13
Name InstanciaEquipeRH: PARAMETROS!$J$15
Name PapelEquipeRH: PARAMETROS!$K$15
Name InstanciaEquipeSW: PARAMETROS!$J$13
Name ColunaSelecaoRH: PARAMETROS!$L$15
Name DadosAreas: 'ÁREAS'!$5:$35
Name ColunaNumParticipantesSV: PARAMETROS!$O$14
Name CNPJ2: DADOS_EMPRESA!$B$12
Name InstanciasSV: PARAMETROS!$F$14
Name TaxaSoftexAssociado: PARAMETROS!$F$3:$F$9
Name SelecaoEntrevista: PARAMETROS!$D$30:$D$31
Name ProcessosSW: PARAMETROS!$E$13
Name RazaoSocial: DADOS_EMPRESA!$B$3
Name TipoProjeto: PARAMETROS!$D$19:$D$27
Name ColunaGerenteSV: PARAMETROS!$N$14
Name InstanciasAvaliacao: PLANO!$A$17:$A$26
Name VersoesModelosMPS: PARAMETROS!$A$3:$A$9
Name ColunaSelecaoSW: PARAMETROS!$L$13
Name SelecaoAvaliacao: PARAMETROS!$J$19:$J$27
Name ProcessosModeloAvaliado: PARAMETROS!$D$104:$D$121
Name ParticipacaoProjetoSOFTEX: PARAMETROS!$A$45:$A$46
Name AbaInstanciaRH: PARAMETROS!$E$21
Name MetodoAvaliacao: DADOS_AVAL!$B$11:$E$11
Name EnderecoUO2: DADOS_EMPRESA!$B$13
Name ColunaInstanciaSV: PARAMETROS!$M$14
Name SituacoesInstanciasModeloSelecionado: PARAMETROS!$A$104:$A$111
Name ModeloRH: PARAMETROS!$C$83:$D$100
Name DadosServiços: 'SERVIÇOS'!$5:$35

Sheet DADOS_EMPRESA
A1: DADOS DA EMPRESA
A3: Razão Social: | B3: Timeware Brasil Softwares e Serviços LTDA
A4: Ano de fundação da organização: | B4: 2019
A5: Cidade: | B5: São Paulo
A6: UF: | B6: SP
A7: Unidade Organizacional (UO): | B7: Fábrica de Software
A8: 1o Local:
A9: CNPJ: | B9: 34.028.046/0001-30
A10: Endereço Completo da UO: (logradouro, cidade, estado, país, CEP) | B10: Av. Pres. Juscelino Kubitschek, 2041, Bloco B, Andar 5, Sala 5070, Vila Nova Conceição, São Paulo/SP, Brasil, CEP 04543-011
A11: 2o Local (opcional):
A12: CNPJ:
A13: Endereço Completo da UO: (logradouro, cidade, estado, país, CEP)
A14: 3o Local (opcional):
A15: CNPJ:
A16: Endereço Completo da UO: (logradouro, cidade, estado, país, CEP)
A17: {="No. de colaboradores da UO envolvidos com " & INDIRECT("Processos" & SIGLA_MODELO()) & ":"} | B17: 21
A18: Descrição das atividades da UO: | B18: Unidade responsável pelo desenvolvimento, manutenção e sustentação de sistemas e soluções de software para clientes públicos e privados.
A19: Site: | B19: https://timeware.com.br/
A20: Facebook:
A21: Natureza Jurídica: | B21: Sociedade Empresária Limitada
A22: CNAE principal da Empresa (Classificação Nacional de Atividades Econômicas): | B22: 62.01-5-01
A23: Faixa da Receita operacional bruta anual da empresa, no ano ANTERIOR, de acordo com a classificação do BNDES: | B23: Pequena empresa (Maior que R$ 2,4 milhões e menor ou igual a R$ 16 milhões)
A24: Porte da empresa com base no número de empregados de acordo com o SEBRAE (Comércio e Serviços): | B24: Média empresa (de 50 a 99)
A25: Patrocinador da avaliação
A26: Nome completo: | B26: Tiago Barbosa Nascimento
A27: E-mail: | B27: tiago.nascimento@timeware.com.br
A28: Telefone comercial: | B28: 55 11 97631-4331
A29: Telefone celular: | B29: 55 11 97631-4331
A30: Cargo: | B30: Founder e CEO
A31: Coordenador Local da avaliação:
A32: Nome completo: | B32: Abraão Alves de Oliveira
A33: E-mail: | B33: abraao.oliveira@timeware.com.br
A34: Telefone comercial: | B34: 55 11 95499-6078
A35: Telefone celular: | B35: 55 11 95499-6078
A36: Cargo: | B36: Gerente Comercial e de Operações

Sheet DADOS_AVAL
A1: DADOS PARA AVALIAÇÃO
A3: Serviços Contratados
A4: Curso de Introdução (C1-MPS) | C4: Não se aplica | D4: Data do curso:
A5: Curso de Preparação de Representante da Empresa (CR-MPS) - Níveis G e F | C5: Sim | D5: Data do curso: | E5: 46191
A6: Curso de Preparação de Representante da Empresa (CR-MPS) - Níveis E, D e C | C6: Sim | D6: Data do curso: | E6: 46191
A7: Curso de Preparação de Representante da Empresa (CR-MPS) - Níveis B e A | C7: Não se aplica | D7: Data do curso:
A8: Escopo da Avaliação
A9: Modelo a ser avaliado: | B9: MPS-SW Versão 2024
A10: Nível solicitado: | B10: C - Definido
A11: Método de avaliação: | B11: MA-MPS (Guia de Avaliação:2024)
A12: Data avaliação inicial: | B12: 46195 | D12: Data final avaliação inicial: | E12: 46197
A13: Data avaliação final: | B13: 46216 | D13: Data final avaliação final: | E13: 46217
A14: Formato da avaliação inicial: | B14: Remoto | D14: Formato da avaliação final: | E14: Remoto
A15: Instituições Envolvidas
A16: IA (Razão Social): | B16: ASR CONSULTORIA E ASSESSORIA EM QUALIDADE LTDA
A17: IOGE: | B17: Não se aplica
A18: II: | B18: Não se aplica
A19: Nome do Implementador Credenciado: | B19: Não se aplica
A20: Composição da Equipe de Avaliação
A21: Avaliador líder: | B21: Ana Zabeu | D21: E-mail: | E21: anazabeu@asrconsultoria.com.br
A22: Observador do Avaliador líder: | B22: Não se aplica | D22: E-mail:
A23: Avaliador adjunto da IA (1): | B23: Johnny Marques | D23: E-mail: | E23: johnnymarques@asrconsultoria.com.br
A24: Avaliador adjunto da IA (2): | B24: Não se aplica | D24: E-mail:
A25: Avaliador adjunto da IA (3): | B25: Não se aplica | D25: E-mail:
A26: Outros avaliadores (1): | B26: Não se aplica | D26: E-mail:
A27: Outros avaliadores (2): | B27: Não se aplica | D27: E-mail:
A28: Representante(s) da Unidade Organizacional:
A29: Nome do Representante | B29: E-mail | C29: Tipo de Curso | D29: Local do Curso (Cidade/UF) | E29: Data do Curso
A30: Cezar Hiraki | B30: cezar.hiraki@timeware.com.br | C30: SW | D30: remoto | E30: 46191
A33: CONTRIBUIÇÃO A SER PAGA À SOFTEX
A34: Indicar instituição que fará o pagamento | C34: a empresa
A35: Participa de projeto da Softex Nacional? | C35: Não | E35: VALOR TOTAL
A36: Empresa associada a agente Softex? | C36: Não
D37: VALOR | E37: =IF(OR(C35="Sim", C36="Sim"),VLOOKUP(NivelSolicitado,TaxasSOFTEX,3,FALSE), VLOOKUP(NivelSolicitado,TaxasSOFTEX,2,FALSE))

Sheet PROJETOS
A1: Seleção de Projetos | C1: Obs.: Caso a avaliação seja do MPS-SW, deixar visível esta aba (Projetos) e ocultar (mas não apagar) as abas Serviços e Áreas.
A2: Quantidade de projetos total executados na UO : | C2: 8
A3: Número de Gerêntes de Projetos na UO: | C3: 1
A4: Nome do projeto | B4: Descrição | C4: Tipo de projeto | D4: Cliente | E4: Ciclo de vida utilizado | F4: Esforço horas | G4: Total de envolvidos no projeto | H4: Gerente do Projeto | I4: Data início | J4: Data término | K4: Fase em que se encontra | L4: Importância para a organização | M4: Seleção para avaliação | N4: Justificativa para seleção do projeto
A5: FTFRUKI — Super App Força de Vendas | B5: Desenvolvimento de módulos do SuperApp Fruki (aplicativo mobile de força de vendas em React Native): Pacote 1 — módulo de Metas e Remuneração Variável; Pacote Final 24 — módulos de Pedidos Não Alocados, Regra de Ouro e PDV. | C5: Evolução Produto | D5: Fruki Bebidas S.A. | E5: Concluído | F5: 2058 | G5: 5 | H5: Abraão Oliveira | I5: 45813 | J5: 46037 | K5: Concluído | L5: Alta | M5: Sim | N5: Projeto com conjunto completo de evidências MPS; duas fases documentadas com TAPs, planos, atas de acompanhamento, relatórios de V&V e lições aprendidas.
A6: AASP — Andamento Processuais | B6: Refatoração da solução legada de captura de andamentos processuais para arquitetura DataJud/CNJ + WorkerAndamentos, com integração EPROC/ESAJ, RabbitMQ e Elasticsearch. | C6: Evolução Produto | D6: AASP — Associação dos Advogados de São Paulo | E6: Construção | F6: 362 | G6: 5 | H6: Abraão Oliveira | I6: 46006 | K6: Construção | L6: Alta | M6: Sim | N6: Projeto com evidências de todas as fases do processo-padrão; refatoração arquitetural documentada em quatro fases com atas de acompanhamento.
A7: PROFARMA / D1000 — Cadastro de Clientes | B7: Desenvolvimento do novo sistema de Cadastro de Clientes da Rede D1000 em .NET/Azure (Clean Architecture + PostgreSQL), substituindo base legada ITEC. Integração com VTEX, BlueSoft, Propz CRM e PBM; piloto na loja 9. | C7: Desenvolvimento | D7: Profarma S.A. / Rede D1000 | E7: Concluído | F7: 5789 | G7: 9 | H7: Abraão Oliveira | I7: 45733 | J7: 46051 | K7: Concluído | L7: Alta | M7: Sim | N7: Maior projeto em complexidade técnica e tamanho de equipe; ciclo de vida completo com evidências abrangentes de todos os processos MPS-SW Nível C.
A8: AASP — CNJ Integração | B8: Desenvolvimento de agente de captura de andamentos processuais via API DataJud/CNJ (WorkerAndamentos), consumindo RabbitMQ e consolidando histórico no Elasticsearch; integração com EPROC/ESAJ. | C8: Desenvolvimento | D8: AASP — Associação dos Advogados de São Paulo | E8: Construção | F8: 624 | G8: 7 | H8: Abraão Oliveira | I8: 45931 | J8: 46203 | K8: Construção | L8: Alta | M8: Sim | N8: Projeto com evidências de todos os processos MPS; contexto de implantação em produção documenta o ciclo completo de desenvolvimento até entrega.

Sheet SERVIÇOS
A1: Seleção de Operações/Instâncias | C1: Obs.: Caso a avaliação seja do MPS-SV, deixar visível esta aba (Serviços) e ocultar (mas não apagar) as abas Projetos e Áreas.
A2: Quantidade de operações/instâncias total executados na UO:
A3: Número de Gestores de Serviços na UO:
A4: Nome das operações / instâncias | B4: Descrição | C4: Cliente | D4: Gerente da Operação / Instância | E4: Esforço horas | F4: Total de envolvidos na operação/ instância | G4: Data início | H4: Data término | I4: Fase em que se encontra | J4: Importância para a organização | K4: Seleção para avaliação | L4: Justificativa para seleção da operação

Sheet ÁREAS
A1: Seleção de Áreas | C1: Obs.: Caso a avaliação seja do MPS-RH, deixar visível esta aba (Áreas) e ocultar (mas não apagar) as abas Projetos e Serviços.
A2: Quantidade de projetos total executados na UO:
A3: Número de Gerentes de Áreas na UO:
A4: Nome da área | B4: Descrição das principais atividades/ atribuições | C4: Esforço horas | D4: Total de envolvidos na área | E4: Gerente da Área | F4: Seleção para avaliação | G4: Justificativa para seleção da área

Sheet PLANO
A1: PLANO DA AVALIAÇÃO
A3: Exclusões de processos e resultados
A4: Processo | B4: Resultado(s) | C4: Justificativa
A5: Não se aplica
A7: Cronograma Geral da Avaliação
A8: Atividade | C8: Responsável | D8: Data Início | E8: Data Fim
A9: Envio dos documentos para preenchimento | C9: Avaliador Líder
A10: Preenchimento das informações da Avaliação | C10: Empresa
A11: Preenchimento da Planilha de Indicadores | C11: Empresa
A12: Avaliação inicial | C12: Equipe de Avaliação | D12: =DADOS_AVAL!B12 | E12: =DADOS_AVAL!E12
A13: Avaliação final | C13: Equipe de Avaliação | D13: =DADOS_AVAL!B13 | E13: =DADOS_AVAL!E13
A14: Publicação do resultado da avaliação no site SOFTEX | C14: SOFTEX | D14: Após cumpridas as formalidades da avaliação
A15: {=INDIRECT("Instancias" & mid(ModeloAvaliado,5,2)) & " Selecionados para a Avaliação"}
A16: Nome | B16: {=INDIRECT("GestorInstancias" & SIGLA_MODELO())} | C16: No. de Participantes | D16: {=INDIRECT("ReferenciaInstancia" & SIGLA_MODELO())} | E16: {=INDIRECT("StatusInstancias" & SIGLA_MODELO())}
A17: FTFRUKI — Super App Força de Vendas | B17: =iferror(vlookup($A17,InstanciasSelecionadas,2,false),"-") | C17: =iferror(vlookup($A17,InstanciasSelecionadas,3,false),"-") | D17: Concluído | E17: =iferror(vlookup($A17,InstanciasSelecionadas,4,false),"-")
A18: AASP — Andamento Processuais | B18: =iferror(vlookup($A18,InstanciasSelecionadas,2,false),"-") | C18: =iferror(vlookup($A18,InstanciasSelecionadas,3,false),"-") | D18: Fase 5 — Implantação | E18: =iferror(vlookup($A18,InstanciasSelecionadas,4,false),"-")
A19: PROFARMA / D1000 — Cadastro de Clientes | B19: =iferror(vlookup($A19,InstanciasSelecionadas,2,false),"-") | C19: =iferror(vlookup($A19,InstanciasSelecionadas,3,false),"-") | D19: Concluído | E19: =iferror(vlookup($A19,InstanciasSelecionadas,4,false),"-")
A20: AASP — CNJ Integração | B20: =iferror(vlookup($A20,InstanciasSelecionadas,2,false),"-") | C20: =iferror(vlookup($A20,InstanciasSelecionadas,3,false),"-") | D20: Fase 7 — Homologação / Encerramento | E20: =iferror(vlookup($A20,InstanciasSelecionadas,4,false),"-")
B21: =iferror(vlookup($A21,InstanciasSelecionadas,2,false),"-") | C21: =iferror(vlookup($A21,InstanciasSelecionadas,3,false),"-") | E21: =iferror(vlookup($A21,InstanciasSelecionadas,4,false),"-")
B22: =iferror(vlookup($A22,InstanciasSelecionadas,2,false),"-") | C22: =iferror(vlookup($A22,InstanciasSelecionadas,3,false),"-") | E22: =iferror(vlookup($A22,InstanciasSelecionadas,4,false),"-")
B23: =iferror(vlookup($A23,InstanciasSelecionadas,2,false),"-") | C23: =iferror(vlookup($A23,InstanciasSelecionadas,3,false),"-") | E23: =iferror(vlookup($A23,InstanciasSelecionadas,4,false),"-")
B24: =iferror(vlookup($A24,InstanciasSelecionadas,2,false),"-") | C24: =iferror(vlookup($A24,InstanciasSelecionadas,3,false),"-") | E24: =iferror(vlookup($A24,InstanciasSelecionadas,4,false),"-")
B25: =iferror(vlookup($A25,InstanciasSelecionadas,2,false),"-") | C25: =iferror(vlookup($A25,InstanciasSelecionadas,3,false),"-") | E25: =iferror(vlookup($A25,InstanciasSelecionadas,4,false),"-")
B26: =iferror(vlookup($A26,InstanciasSelecionadas,2,false),"-") | C26: =iferror(vlookup($A26,InstanciasSelecionadas,3,false),"-") | E26: =iferror(vlookup($A26,InstanciasSelecionadas,4,false),"-")

Sheet ACORDO_CONFIDENCIALIDADE
A2: Acordo de Confidencialidade para Avaliação MPS
A3: O presente acordo é feito para facilitar uma discussão aberta e franca dos processos da organização avaliada, de maneira que os problemas críticos possam ser abordados e os respectivos processos melhorados. Este acordo estabelece um entendimento mútuo, entre a equipe de avaliadores MPS e aqueles que participam da avaliação, de que os seguintes pontos serão observados no tratamento de toda informação recolhida durante a avaliação e após a mesma, de maneira permanente. 1 - Em conformidade com o disposto na Norma ISO/IEC 33002:2015, toda informação pertinente à avaliação e que suportará a compreensão dos seus resultados, deverá ser compilada e incluída no registro da avaliação, para retenção pelo patrocinador da avaliação ou sua autoridade delegada na organização avaliada. 2 - Os membros da equipe de avaliadores, individual e coletivamente, concordam em tratar como confidencial toda informação coletada de revisões de artefatos e entrevistas. Esta informação não será relatada a ninguém fora da equipe de avaliação, de maneira que possam ser identificadas pessoas ou projetos como fontes de informação. 3 - Os resultados da avaliação e qualquer outra informação contida nas suas conclusões, recomendações e relatório final, serão apresentadas somente de forma sumária, de maneira que nenhuma pessoa ou projeto possa ser identificado. 4 - Cada participante da avaliação (membros da equipe de avaliação e entrevistados) concorda em não discutir, comunicar ou compartilhar informação que tenha obtido durante as entrevistas ou discussões de avaliação com nenhuma outra pessoa que não pertença à equipe de avaliação. Para continuar participando da avaliação, cada participante aceita acatar os princípios de confidencialidade aqui estabelecidos. 5 - Todas as conclusões desta avaliação são propriedade da organização avaliada e não podem ser discutidas, comunicadas ou distribuídas de forma alguma, fora da organização avaliada, sem a aprovação do patrocinador da avaliação, abaixo assinado. 6 - Uma cópia dos resultados da avaliação será mantida em uma base de dados confidencial pelo Avaliador-líder, abaixo assinado, podendo ser utilizada posteriormente para análises ou pesquisas solicitadas pela organização avaliada. A informação resultante destas análises deverá estar de acordo com os pontos 2-4 acima mencionados. 7 - Uma cópia dos resultados da avaliação será armazenada em uma base de dados confidencial da Sociedade Softex, coordenadora do Programa MPS.BR, podendo ser utilizada para fins de pesquisas.
A4: 8- Os resultados oficiais da avaliação serão disponibilizados no Portal SOFTEX (www.softex.br/mpsbr). Apenas a publicação do resultado da avaliação – Declaração da Avaliação de Processos - no site da SOFTEX tem validade oficial. Após o período de 3 anos (período de validade da avaliação) o resultado será retirado do Portal SOFTEX (www.softex.br/mpsbr) e não será concedida extensão de prazo de validade, em hipótese alguma. RETIRAR ESTA LINHA SE A OPÇÃO DA EMPRESA FOR: NÃO PUBLICAR O RESULTADO
A5: 8- A empresa não autoriza a Sociedade SOFTEX a publicar os resultados desta avaliação no Portal SOFTEX (www.softex.br/mpsbr). Como consequência a Declaração da Avaliação de Processos não poderá ser disponibilizada pela SOFTEX. Como o resultado não ser tornado público, a empresa só poderá utilizá-lo internamente. RETIRAR ESTA LINHA SE A OPÇÃO DA EMPRESA FOR: PUBLICAR O RESULTADO
A6: 9- A SOFTEX não emite atestados ou quaisquer outras declarações em relação à avaliação oficial ou à sua validade que não esteja publicado no Portal SOFTEX (www.softex.br/mpsbr).
A8: As assinaturas abaixo expressam a concordância quanto ao cumprimento dos termos deste acordo, por prazo indeterminado.
A10: Local e data: | B10: =CidadeUnidadeOrganizacional & ", " & DAY(PLANO!D12) & "/" & Month(PLANO!D12) & "/" & Year(PLANO!D12)
A12: RETIRAR ESTA LINHA ANTES DE SOLICITAR AS ASSINATURAS. Rever as linhas abaixo para refletir os papéis desempenhados nesta avaliação, deixar apenas os papéis pertinentes. O documento deve ser assinado eletronicamente em plataforma com certificado digital ICP.
A13: Membros da Equipe de Avaliação:
A15: Avaliador Líder: | B15: =DADOS_AVAL!B21
A17: Avaliador Adjunto: | B17: =DADOS_AVAL!B23
A19: Avaliador Adjunto: | B19: =DADOS_AVAL!B24
A21: Avaliador Adjunto: | B21: =DADOS_AVAL!B25
A23: Avaliador Adjunto: | B23: =DADOS_AVAL!B26
A25: Avaliador Adjunto: | B25: =DADOS_AVAL!B27
A27: Observador do Avaliador líder: | B27: =DADOS_AVAL!B22
A29: Representante da Empresa: | B29: =DADOS_AVAL!A30
A31: Representante da Empresa: | B31: =DADOS_AVAL!A32
A33: Organização Avaliada (Patrocinador da avaliação): | B33: =RazaoSocial & ", " & NomePatrocinador & ", " & CargoPatrocinador
A35: Sociedade Softex: | B35: Gestor MPSBR Softex

Sheet EQUIPE
A1: {=UPPER("EQUIPE ENVOLVIDA COM " & INDIRECT("Processos" & SIGLA_MODELO()))}
A3: Seleção Entrevista | B3: Nome | C3: {=INDIRECT("InstanciaEquipe" & mid(ModeloAvaliado,5,2))} | D3: {=INDIRECT("PapelEquipe" & mid(ModeloAvaliado,5,2))} | E3: Cargo organizacional | F3: Nome da Chefia | H3: Instâncias na Avaliação | I3: Qtd.
A4: Sim | B4: Abraão Oliveira | C4: FTFRUKI — Super App Força de Vendas | D4: Gerente de Projeto / Product Owner | E4: Gerente de Projetos | F4: Wilson Yamada | H4: {=PLANO!A17:A26} | I4: =COUNTIFS($C$4:$C$500,H4)
A5: Não | B5: Luca Watson | C5: FTFRUKI — Super App Força de Vendas | D5: Desenvolvedor Front-End (React Native) | E5: Desenvolvedor | F5: Abraão Oliveira | I5: =COUNTIFS($C$4:$C$500,H5)
A6: Não | B6: Thiago Gomes | C6: FTFRUKI — Super App Força de Vendas | D6: Desenvolvedor Front-End (React Native) | E6: Desenvolvedor | F6: Abraão Oliveira | I6: =COUNTIFS($C$4:$C$500,H6)
A7: Não | B7: Brenda Chrystie | C7: FTFRUKI — Super App Força de Vendas | D7: UX/UI Designer / Analista de Negócio | E7: Designer UX/UI | F7: Abraão Oliveira | I7: =COUNTIFS($C$4:$C$500,H7)
A8: Não | B8: Tiago Barbosa Nascimento | C8: FTFRUKI — Super App Força de Vendas | D8: COO / Gestão Comercial | E8: CEO / Founder | I8: =COUNTIFS($C$4:$C$500,H8)
A9: Sim | B9: Abraão Oliveira | C9: AASP — Andamento Processuais | D9: Gerente de Projeto | E9: Gerente de Projetos | F9: Wilson Yamada | I9: =COUNTIFS($C$4:$C$500,H9)
A10: Sim | B10: Cézar Hiraki Velázquez | C10: AASP — Andamento Processuais | D10: Tech Lead / Arquiteto / DevOps | E10: Arquiteto de Software | F10: Abraão Oliveira | I10: =COUNTIFS($C$4:$C$500,H10)
A11: Não | B11: Raony Chagas | C11: AASP — Andamento Processuais | D11: Desenvolvedor Sênior | E11: Desenvolvedor Sênior | F11: Cézar Hiraki Velázquez | I11: =COUNTIFS($C$4:$C$500,H11)
A12: Não | B12: Mateus Veloso | C12: AASP — Andamento Processuais | D12: Desenvolvedor (Suporte) | E12: Desenvolvedor | F12: Cézar Hiraki Velázquez | I12: =COUNTIFS($C$4:$C$500,H12)
A13: Não | B13: Caroline Sousa | C13: AASP — Andamento Processuais | D13: Analista de QA | E13: Analista de QA | F13: Abraão Oliveira | I13: =COUNTIFS($C$4:$C$500,H13)
A14: Sim | B14: Abraão Oliveira | C14: PROFARMA / D1000 — Cadastro de Clientes | D14: Gerente de Projeto / Account Manager | E14: Gerente de Projetos | F14: Wilson Yamada
A15: Sim | B15: Cézar Hiraki Velázquez | C15: PROFARMA / D1000 — Cadastro de Clientes | D15: Tech Lead / DevOps / Arquiteto | E15: Arquiteto de Software | F15: Abraão Oliveira
A16: Não | B16: Mateus Veloso | C16: PROFARMA / D1000 — Cadastro de Clientes | D16: Dev Backend | E16: Desenvolvedor | F16: Cézar Hiraki Velázquez
A17: Não | B17: Raony Chagas | C17: PROFARMA / D1000 — Cadastro de Clientes | D17: Dev Backend | E17: Desenvolvedor Sênior | F17: Cézar Hiraki Velázquez
A18: Não | B18: Lucas Batista | C18: PROFARMA / D1000 — Cadastro de Clientes | D18: Dev Backend | E18: Desenvolvedor | F18: Cézar Hiraki Velázquez
A19: Não | B19: Caroline Sousa | C19: PROFARMA / D1000 — Cadastro de Clientes | D19: QA / Testes Automatizados | E19: Analista de QA | F19: Abraão Oliveira
A20: Sim | B20: Abraão Oliveira | C20: AASP — CNJ Integração | D20: Gerente de Projeto | E20: Gerente de Projetos | F20: Wilson Yamada
A21: Sim | B21: Cézar Hiraki Velázquez | C21: AASP — CNJ Integração | D21: Tech Lead / DevOps / Arquiteto | E21: Arquiteto de Software | F21: Abraão Oliveira
A22: Não | B22: Raony Chagas | C22: AASP — CNJ Integração | D22: Desenvolvedor Sênior (Principal) | E22: Desenvolvedor Sênior | F22: Cézar Hiraki Velázquez
A23: Não | B23: Mateus Veloso | C23: AASP — CNJ Integração | D23: Desenvolvedor | E23: Desenvolvedor | F23: Cézar Hiraki Velázquez
A24: Não | B24: Lucas Batista | C24: AASP — CNJ Integração | D24: Desenvolvedor | E24: Desenvolvedor | F24: Cézar Hiraki Velázquez
A25: Não | B25: Caroline Sousa | C25: AASP — CNJ Integração | D25: Analista de QA | E25: Analista de QA | F25: Abraão Oliveira
A26: Não | B26: Jonathan Barbosa | C26: AASP — CNJ Integração | D26: Auditor GQA (independente) | E26: Analista de Qualidade | F26: Abraão Oliveira

Sheet EQUIPE_ORG
B1: EQUIPE ENVOLVIDA COM OS PROCESSOS ORGANIZACIONAIS
A3: Seleção Entrevista | B3: Nome | C3: Processo organizacional da UO | D3: Papel no processo da UO | E3: Cargo organizacional | F3: Nome da Chefia
A4: Sim | B4: Wilson Yamada | C4: OSW — Gerência Organizacional de Software | D4: COO / Responsável OSW e Portfólio | E4: COO (Chief Operating Officer) | F4: Tiago Barbosa Nascimento
A5: Sim | B5: Silvio Baroni | C5: GPC — Gerência de Processos | D5: Coordenador do Time de Melhoria Contínua (SEPG) | E5: Gerente de Produto Sênior | F5: Wilson Yamada
A6: Sim | B6: Silvio Baroni | C6: MED — Medição | D6: Responsável de Medição | E6: Gerente de Produto Sênior | F6: Wilson Yamada
A7: Sim | B7: Abraão Oliveira | C7: GPC — Gerência de Processos | D7: Membro do Time de Melhoria Contínua (SEPG) | E7: Gerente de Projetos | F7: Wilson Yamada
A8: Sim | B8: Caroline Jenifer | C8: GPC — Gerência de Processos | D8: GQA — Garantia da Qualidade de Processo (independente) | E8: Analista de QA Sênior | F8: Abraão Oliveira
A9: Sim | B9: Flávio Fernandes | C9: GCO — Gerência de Configuração | D9: DevOps / GCO Baseline e Auditoria | E9: Engenheiro DevOps | F9: Cézar Hiraki Velázquez
A10: Sim | B10: Guilherme Gomes | C10: CAP — Capacitação | D10: Responsável de RH / Capacitação | E10: Analista de RH | F10: Wilson Yamada
A11: Não | B11: Klayton Roberto | C11: CAP — Capacitação | D11: Apoio RH / Capacitação | E11: Analista de RH | F11: Guilherme Gomes
A12: Não | B12: Patricia Lima | C12: GPC — Gerência de Processos | D12: Membro do Time de Melhoria Contínua (SEPG) | E12: Analista de Processos | F12: Silvio Baroni
A13: Não | B13: Mariana Teixeira | C13: GPC — Gerência de Processos | D13: Membro do Time de Melhoria Contínua (SEPG) | E13: Analista de Processos | F13: Silvio Baroni

Sheet CRONOGRAMA_INICIAL
A1: CRONOGRAMA DE ATIVIDADES DA AVALIAÇÃO INICIAL
A3: =PLANO!D12
A4: Início | B4: Fim | C4: Duração | D4: Atividade | E4: Participantes
A5: 0.35416667 | B5: =A5+C5 | C5: 0.013888889 | D5: Reunião da equipe de avaliação com o patrocinador | E5: Patrocinador, coordenador e equipe de avaliação
A6: =B5 | B6: =A6+C6 | C6: 0.020833333 | D6: Apresentação dos processos da organização à equipe de avaliação | E6: Equipe de Avaliação e participantes da avaliação inicial
A7: =B6 | B7: =A7+C7 | C7: 0.020833333 | D7: Treinamento da equipe de avaliação | E7: Avaliador Líder e Membros da equipe de avaliação
A8: =B7 | B8: =A8+C8 | C8: 0.090277778 | D8: Revisão das Planilhas e elaboração do Relatório de Ajustes | E8: Equipe de Avaliação e participantes da avaliação inicial
A9: =B8 | B9: =A9+C9 | C9: 0.0625 | D9: Almoço
A10: =B9 | B10: =A10+C10 | C10: 0.10416667 | D10: Revisão das Planilhas e elaboração do Relatório de Ajustes | E10: Equipe de Avaliação e participantes da avaliação inicial
A11: =B10 | B11: =A11+C11 | C11: 0.010416667 | D11: Intervalo para café
A12: =B11 | B12: =A12+C12 | C12: 0.072916667 | D12: Revisão das Planilhas e elaboração do Relatório de Ajustes | E12: Equipe de Avaliação e participantes da avaliação inicial
A13: =B12 | B13: =A13+C13 | D13: Encerramento das atividades do dia
A15: Início | B15: Fim | C15: Duração | D15: Atividade | E15: Participantes
A16: 0.35416667 | B16: =A16+C16 | C16: 0.0625 | D16: Revisão das Planilhas e elaboração do Relatório de Ajustes | E16: Equipe de Avaliação e participantes da avaliação inicial
A17: =B16 | B17: =A17+C17 | C17: 0.010416667 | D17: Intervalo para café
A18: =B17 | B18: =A18+C18 | C18: 0.072916667 | D18: Revisão das Planilhas e elaboração do Relatório de Ajustes | E18: Equipe de Avaliação e participantes da avaliação inicial
A19: =B18 | B19: =A19+C19 | C19: 0.0625 | D19: Almoço
A20: =B19 | B20: =A20+C20 | C20: 0.10416667 | D20: Revisão das Planilhas e elaboração do Relatório de Ajustes | E20: Equipe de Avaliação e participantes da avaliação inicial
A21: =B20 | B21: =A21+C21 | C21: 0.010416667 | D21: Intervalo para café
A22: =B21 | B22: =A22+C22 | C22: 0.072916667 | D22: Revisão das Planilhas e elaboração do Relatório de Ajustes | E22: Equipe de Avaliação e participantes da avaliação inicial
A23: =B22 | B23: =A23+C23 | D23: Encerramento das atividades do dia
A24: =PLANO!E12
A25: Início | B25: Fim | C25: Duração | D25: Atividade | E25: Participantes
A26: 0.35416667 | B26: =A26+C26 | C26: 0.0625 | D26: Revisão das Planilhas e elaboração do Relatório de Ajustes | E26: Equipe de Avaliação e participantes da avaliação inicial
A27: =B26 | B27: =A27+C27 | C27: 0.010416667 | D27: Intervalo para café
A28: =B27 | B28: =A28+C28 | C28: 0.072916667 | D28: Revisão das Planilhas e elaboração do Relatório de Ajustes | E28: Equipe de Avaliação e participantes da avaliação inicial
A29: =B28 | B29: =A29+C29 | C29: 0.0625 | D29: Almoço
A30: =B29 | B30: =A30+C30 | C30: 0.083333333 | D30: Revisão das Planilhas e elaboração do Relatório de Ajustes | E30: Equipe de Avaliação e participantes da avaliação inicial
A31: =B30 | B31: =A31+C31 | C31: 0.010416667 | D31: Intervalo para café
A32: =B31 | B32: =A32+C32 | C32: 0.052083333 | D32: Reunião com o patrocinador para presentação do Relatório de Ajustes e Relatório Inicial | E32: Patrocinador, coordenador, equipe de avaliação, representante da II e demais participantes da empresa da avaliação inicial.
A33: =B32 | B33: =A33+C33 | D33: Encerramento da avaliação inicial

Sheet CRONOGRAMA_FINAL
A1: CRONOGRAMA DE ATIVIDADES DA AVALIAÇÃO FINAL
A3: =PLANO!D13
A4: Início | B4: Fim | C4: Duração | D4: Atividade | E4: Participantes
A5: 0.35416667 | B5: =A5+C5 | C5: 0.010416667 | D5: Reunião da equipe de avaliação com o patrocinador | E5: Patrocinador, coordenador e equipe de Avaliação
A6: =B5 | B6: =A6+C6 | C6: 0.020833333 | D6: Reunião de abertura | E6: Equipe de avaliação, patrocinador e todos os entrevistados
A7: =B6 | B7: =A7+C7 | C7: 0.020833333 | D7: Treinamento da equipe de avaliação | E7: Avaliador líder e membros da equipe de avaliação
A8: =B7 | B8: =A8+C8 | C8: 0.041666667 | D8: Revisão das Planilhas e do Relatório de Ajustes | E8: Avaliador líder e membros da equipe de avaliação
A9: =B8 | B9: =A9+C9 | C9: 0.010416667 | D9: Intervalo para café
A10: =B9 | B10: =A10+C10 | C10: 0.041666667 | D10: Entrevista com {nome do papel da UO} (processos do MPS que serão tratados) | E10: Equipe de avaliação e
A11: =B10 | B11: =A11+C11 | C11: 0.0625 | D11: Almoço
A12: =B11 | B12: =A12+C12 | C12: 0.03125 | D12: Entrevista com | E12: Equipe de avaliação e
A13: =B12 | B13: =A13+C13 | C13: 0.03125 | D13: Entrevista com | E13: Equipe de avaliação e
A14: =B13 | B14: =A14+C14 | C14: 0.03125 | D14: Entrevista com | E14: Equipe de avaliação e
A15: =B14 | B15: =A15+C15 | C15: 0.010416667 | D15: Intervalo para café
A16: =B15 | B16: =A16+C16 | C16: 0.03125 | D16: Entrevista com | E16: Equipe de avaliação e
A17: =B16 | B17: =A17+C17 | C17: 0.03125 | D17: Entrevista com | E17: Equipe de avaliação e
A18: =B17 | B18: =A18+C18 | C18: 0.020833333 | D18: Revisão da documentação | E18: Equipe de avaliação
A19: =B18 | B19: =A19+C19 | D19: Encerramento das atividades do dia
A21: Início | B21: Fim | C21: Duração | D21: Atividade | E21: Participantes
A22: 0.35416667 | B22: =A22+C22 | C22: 0.010416667 | D22: Reunião da equipe de avaliação | E22: Equipe de avaliação
A23: 0.39583333 | B23: =A23+C23 | C23: 0.03125 | D23: Entrevista com | E23: Equipe de avaliação e
A24: 0.4375 | B24: =A24+C24 | C24: 0.03125 | D24: Entrevista com | E24: Equipe de avaliação e
A25: 0.47916667 | B25: =A25+C25 | C25: 0.03125 | D25: Entrevista com | E25: Equipe de avaliação e
A26: 0.52083333 | B26: =A26+C26 | C26: 0.0625 | D26: Almoço
A27: 0.52083333 | B27: =A27+C27 | C27: 0.041666667 | D27: Revisão da documentação | E27: Equipe de avaliação e
A28: 0.5625 | B28: =A28+C28 | C28: 0.010416667 | D28: Entrevista com | E28: Equipe de avaliação e
A29: 0.60416667 | B29: =A29+C29 | C29: 0.010416667 | D29: Entrevista com | E29: Equipe de avaliação e
A30: =B29 | B30: =A30+C30 | C30: 0.010416667 | D30: Intervalo para café
A31: =B30 | B31: =A31+C31 | C31: 0.052083333 | D31: Entrevista com | E31: Equipe de avaliação e
A32: =B31 | B32: =A32+C32 | C32: 0.052083333 | D32: Entrevista com | E32: Equipe de avaliação e
A33: =B32 | B33: =A33+C33 | D33: Encerramento das atividades do dia
A34: =PLANO!E13
A35: Início | B35: Fim | C35: Duração | D35: Atividade | E35: Participantes
A36: 0.35416667 | B36: =A36+C36 | C36: 0.010416667 | D36: Reunião da equipe | E36: Equipe de avaliação e
A37: 0.39583333 | B37: =A37+C37 | C37: 0.03125 | D37: Entrevista com | E37: Equipe de avaliação e
A38: 0.4375 | B38: =A38+C38 | C38: 0.03125 | D38: Entrevista com | E38: Equipe de avaliação e
A39: 0.47916667 | B39: =A39+C39 | C39: 0.03125 | D39: Entrevista com | E39: Equipe de avaliação e
A40: 0.52083333 | B40: =A40+C40 | C40: 0.0625 | D40: Almoço
A41: 0.52083333 | B41: =A41+C41 | C41: 0.041666667 | D41: Revisão da documentação | E41: Equipe de avaliação e
A42: 0.5625 | B42: =A42+C42 | C42: 0.010416667 | D42: Apresentação dos Resultados Preliminares I | E42: Equipe de avaliação e
...

Sheet RESULTADO_INICIAL
A2: Enviar email desse relatório para auditor, SOFTEX, patrocinador, coordenador local (e implementador se houver)
A4: ="Assunto: " & NomeUnidadeOrganizacional & " - Resultado da Avaliação Inicial"
A6: Prezados,
A7: ="A Avaliação MPS-" & SIGLA_MODELO() & " Nível " & NivelSolicitado & " foi finalizada com a(s) seguinte(s) conclusão(ões):"
A8: Representante da II na Avaliação | B8: =DADOS_AVAL!B19
A9: Nível para a avaliação final | B9: G - Parcialmente Gerenciado
A10: Marcar a avaliação final para
A15: Solicito que seja realizada a auditoria.
A16: at.te,
A17: =DADOS_AVAL!C21

Sheet RESULTADO_FINAL
B2: {="RESULTADO DE AVALIAÇÃO DE PROCESSOS DE " & upper(INDIRECT("Processos" & SIGLA_MODELO()))}
B4: =DADOS_EMPRESA!A3 | C4: =RazaoSocial
B5: CNPJ: | C5: =CNPJS_UO()
B6: Unidade Organizacional Avaliada:
B7: Nome: | C7: =NomeUnidadeOrganizacional
B8: Endereço: | C8: =ENDERECOS_UO()
B9: Descrição das Atividades da Unidade Organizacional | C9: =DescricaoAtividadesUO
B10: Patrocinador da avaliação | C10: =DADOS_EMPRESA!B26
B12: Instituição Organizadora de Grupo de Empresas: | C12: =IFERROR(__xludf.DUMMYFUNCTION("IFERROR(join("", "",FILTRAR_NAOSEAPLICA(DADOS_AVAL!B17)),""-"")"),"-")
B13: Instituição Implementadora: | C13: =IFERROR(__xludf.DUMMYFUNCTION("IFERROR(join("", "",FILTRAR_NAOSEAPLICA(DADOS_AVAL!B18)),""-"")"),"-")
B14: Instituição Avaliadora (IA): | C14: =IFERROR(__xludf.DUMMYFUNCTION("IFERROR(join("", "",FILTRAR_NAOSEAPLICA(DADOS_AVAL!B16)),""-"")"),"ASR CONSULTORIA E ASSESSORIA EM QUALIDADE LTDA")
B15: Equipe de Avaliação:
B16: Avaliador Líder: | C16: =DADOS_AVAL!B21
B17: Avaliador(es) Adjunto(s): | C17: =IFERROR(__xludf.DUMMYFUNCTION("IFERROR(join("", "",FILTRAR_NAOSEAPLICA(DADOS_AVAL!B23:B27)),""-"")"),"Johnny Marques")
B18: Observador do Avaliador líder: | C18: =IFERROR(__xludf.DUMMYFUNCTION("IFERROR(join("", "",FILTRAR_NAOSEAPLICA(DADOS_AVAL!B22)),""-"")"),"-")
B19: Avaliador(es) Representante(s) da Unidade Organizacional: | C19: =IFERROR(__xludf.DUMMYFUNCTION("iferror(join("", "",FILTRAR_NAOSEAPLICA(DADOS_AVAL!A30:A32)),""-"")"),"Cezar Hiraki")
B21: Método de avaliação: | C21: =DADOS_AVAL!B11
B22: Data da Avaliação: | C22: =PLANO!E13
B23: Validade da Avaliação: | C23: =IFERROR( EDATE((C22-1),36), )
B24: Modelo MPS | C24: =DADOS_AVAL!B9
B25: Resultado da avaliação: | C25: ="Atendeu aos requisitos de processos e capacidade do Modelo de Referência "& ModeloAvaliado & " do nível " & RESULTADO_INICIAL!B9 & "."
B26: Exclusões de processos e resultados
B27: Processo | C27: =PLANO!B4 | D27: =PLANO!C4
B28: =PLANO!A5 | C28: =PLANO!B5 | D28: =PLANO!C5
B29: =PLANO!A6 | C29: =PLANO!B6 | D29: =PLANO!C6
B31: Processos | C31: Nível Avaliado | D31: Resultado
B32: {=INDIRECT("ProcessosModelo" & SIGLA_MODELO())}
B33: Capacitação
B34: Gerência de Configuração
B35: Gerência de Decisões
B36: Gerência de Processos
B37: Gerência de Projetos
B38: Integração do Produto
B39: Medição
B40: Gerência Organizacional de Software
B41: Projeto e Construção do Produto
B42: Engenharia de Requisitos
B43: Verificação e Validação
B44: Nível G – Parcialmente Gerenciado | D44: Não Avaliado
B45: Nível F – Gerenciado | D45: Não Avaliado
...

Sheet RESULTADO_FINAL_RH
B2: RESULTADO DE AVALIAÇÃO DE PROCESSOS DE RECURSOS HUMANOS
B4: =DADOS_EMPRESA!A3 | C4: =RazaoSocial
B5: CNPJ: | C5: =CNPJS_UO()
B6: Unidade Organizacional Avaliada:
B7: Nome: | C7: =NomeUnidadeOrganizacional
B8: Endereço: | C8: =ENDERECOS_UO()
B9: Descrição das Atividades da Unidade Organizacional | C9: =DescricaoAtividadesUO
B10: Patrocinador da avaliação | C10: =DADOS_EMPRESA!B26
B12: Instituição Organizadora de Grupo de Empresas: | C12: =IFERROR(__xludf.DUMMYFUNCTION("IFERROR(join("", "",FILTRAR_NAOSEAPLICA(DADOS_AVAL!B17)),""-"")"),"-")
B13: Instituição Implementadora: | C13: =IFERROR(__xludf.DUMMYFUNCTION("IFERROR(join("", "",FILTRAR_NAOSEAPLICA(DADOS_AVAL!B18)),""-"")"),"-")
B14: Instituição Avaliadora (IA): | C14: =IFERROR(__xludf.DUMMYFUNCTION("IFERROR(join("", "",FILTRAR_NAOSEAPLICA(DADOS_AVAL!B16)),""-"")"),"ASR CONSULTORIA E ASSESSORIA EM QUALIDADE LTDA")
B15: Equipe de Avaliação:
B16: Avaliador Líder: | C16: =DADOS_AVAL!B21
B17: Avaliador(es) Adjunto(s): | C17: =IFERROR(__xludf.DUMMYFUNCTION("IFERROR(join("", "",FILTRAR_NAOSEAPLICA(DADOS_AVAL!B23:B27)),""-"")"),"Johnny Marques")
B18: Observador do Avaliador líder: | C18: =IFERROR(__xludf.DUMMYFUNCTION("IFERROR(join("", "",FILTRAR_NAOSEAPLICA(DADOS_AVAL!B22)),""-"")"),"-")
B19: Avaliador(es) Representante(s) da Unidade Organizacional: | C19: =IFERROR(__xludf.DUMMYFUNCTION("iferror(join("", "",FILTRAR_NAOSEAPLICA(DADOS_AVAL!A30:A32)),""-"")"),"Cezar Hiraki")
B21: Método de avaliação: | C21: MA-MPS (Guia de Avaliação:2023)
B22: Data da Avaliação: | C22: =PLANO!E13
B23: Validade da Avaliação: | C23: =IFERROR( EDATE((D22-1),36), )
B24: Modelo MPS | C24: =DADOS_AVAL!B9
B25: Resultado da avaliação: | C25: ="Atendeu aos requisitos de processos e capacidade do Modelo de Referência "& DADOS_AVAL!C9 & " do nível " & RESULTADO_INICIAL!B9
B26: Exclusões de processos e resultados
B27: Processo | C27: =PLANO!B4 | D27: =PLANO!C4
B28: =PLANO!A6 | C28: =PLANO!B6 | D28: =PLANO!C6
B30: Nível G – Parcialmente Gerenciado
B31: GRC - Gerência de Recursos | D31: Não Avaliado
B32: GPE - Gerência de Pessoas | D32: Não Avaliado
B33: Nível F – Gerenciado
B34: CDV – Capacitação e Desenvolvimento | D34: Não Avaliado
B35: REC – Reconhecimento | D35: Não Avaliado
B36: Nível E – Parcialmente Definido
B37: ACP – Análise de Competências | D37: Não Avaliado
B38: PFT – Planejamento da Força de Trabalho | D38: Não Avaliado
B39: DGT – Desenvolvimento de Grupos de Trabalho | D39: Não Avaliado
B40: Nível D – Largamente Definido
B41: DVC – Desenvolvimento de Competências | D41: Não Avaliado
B42: PBC – Práticas Baseadas em Competências | D42: Não Avaliado
B43: Nível C – Definido
B44: DCA – Desenvolvimento de Carreira | D44: Não Avaliado
B45: MEN – Mentoring | D45: Não Avaliado
...

Sheet RELATORIO_NIVEIS_AB
A4: Em avaliações de níveis B ou A, enviar junto com a auditoria da avaliação inicial para auditor as seguintes informações:
A6: (i) que baselines de desempenho foram estabelecidas?
A7: (ii)que processos foram estabilizados?
A8: (iii)Que modelos de desempenho foram desenvolvidos com a descrição de cada um contendo:objetivo, variaveis dependentes e variaveis independentes, qual o efeito nas variaveis dependente de diferentes valores nas variáveis independentes
A9: (iv) o que foi verificado com relação à capacidade dos processos para satisfazer os objetivos de negócio

Sheet DECLARACAO_AVALIACAO
B2: {="Avaliação de Processos de " & INDIRECT("Processos" & SIGLA_MODELO())}
B5: {="A Associação para Promoção da Excelência do Software Brasileiro - Softex declara que possui armazenado o resultado da avaliação de processos de " & LOWER(INDIRECT("Processos" & SIGLA_MODELO())) & " da empresa " & DADOS_EMPRESA!B3 & ", CNPJ " & CNPJS_UO() & ", concluída em " & DAY(PLANO!E13) & "/" & MONTH(PLANO!E13) & "/" & YEAR(PLANO!E13) & ", na sua unidade organizacional " & NomeUnidadeOrganizacional & " em " & CidadeUnidadeOrganizacional & " / " & EstadoUnidadeOrganizacional & ", sob o patrocínio de " &DADOS_EMPRESA!B26 & " - " &DADOS_EMPRESA!B30 & "." & " Esta avaliação tem prazo de validade até " & DAY(RESULTADO_FINAL!C23) & "/" & MONTH(RESULTADO_FINAL!C23) & "/" & YEAR(RESULTADO_FINAL!C23) & "."}
B7: ="A avaliação foi conduzida pelo avaliador líder " & DADOS_AVAL!B21 & ", da Instituição Avaliadora (IA) " &DADOS_AVAL!B16 &". Com base no método de avaliação " & MetodoAvaliacao & ", a equipe de avaliação concluiu que a organização atendeu aos requisitos de processos e capacidade do Modelo de Referência " & ModeloAvaliado & " do nível " & RESULTADO_INICIAL!B9 & "."
B10: ="Brasília-DF, " & Day(PLANO!E13) & "/" & Month(PLANO!E13) & "/" & Year(PLANO!E13)
B15: =DADOS_AVAL!B21
B16: Avaliador Líder | D16: Gestor MPSBR SOFTEX
B17: Este documento deve ser assinado eletronicamente em plataforma com certificado digital ICP. Apagar ou esconder essa linha antes de gerar o PDF.

Sheet SOLICITA_FEEDBACK
A1: Enviar email para Thiago Amoras solicitando o envio dos feedbacks, no início da avaliação final (ou dias antes)
A3: PARA: thiago@softex.br
A5: ="ASSUNTO: " & NomeUnidadeOrganizacional & " - Solicitação para envio do Feedback"
A7: Prezado Thiago
A9: Foi/Será realizada avaliação final conforme dados abaixo, solicito o envio do link para o fornecimento dos feedbacks:
A10: Empresa: | B10: =RazaoSocial & " - " & NomeUnidadeOrganizacional
A11: Modelo: | B11: ="MPS-" & SIGLA_MODELO()
A12: Nível: | B12: =NivelSolicitado
A13: Período da Avaliação Final: | B13: =DAY(DADOS_AVAL!B13) & "/" & Month(DADOS_AVAL!B13) & "/" & Year(DADOS_AVAL!B13) & " a " & DAY(DADOS_AVAL!E13) & "/" & Month(DADOS_AVAL!E13) & "/" & Year(DADOS_AVAL!E13)
A15: Seguem os contatos:
A17: 1) Patrocinador | B17: e-mail
A18: =DADOS_EMPRESA!B26 | B18: =DADOS_EMPRESA!B27
A20: 2) Avaliador Líder | B20: e-mail
A21: =DADOS_AVAL!B21 | B21: =DADOS_AVAL!E21
A23: 3) Representantes da empresa | B23: e-mail
A24: =DADOS_AVAL!A30 | B24: =DADOS_AVAL!B30
A25: =DADOS_AVAL!A32 | B25: =DADOS_AVAL!B32
A27: 4) Avaliadores Adjuntos | B27: e-mail
A28: =DADOS_AVAL!B23 | B28: =DADOS_AVAL!E23
A29: =DADOS_AVAL!B24 | B29: =DADOS_AVAL!E24
A30: =DADOS_AVAL!B25 | B30: =DADOS_AVAL!E25
A31: =DADOS_AVAL!B26 | B31: =DADOS_AVAL!E26
A32: =DADOS_AVAL!B27 | B32: =DADOS_AVAL!E27
A34: 5) Auditor | B34: <inserir nome do auditor>
B35: <inserir e-mail do auditor>
A38: Atenciosamente,

Sheet AUDITORIA
A1: ="PARECER SOBRE AVALIAÇÃO MR-MPS-" & SIGLA_MODELO()
A3: Empresa | B3: =RazaoSocial
A4: Nível pretendido: | B4: =NivelSolicitado
A5: Nível obtido: | B5: =RESULTADO_INICIAL!B9
A6: Auditor: | B6: =SOLICITA_FEEDBACK!B34
A7: Data auditoria inicial | C7: Data auditoria final
A9: AUDITORIA DA AVALIAÇÃO INICIAL
A10: Apreciação sobre o resultado da avaliação MPS na empresa: | C10: Justificativa:
A11: Parecer Final sobre a Avaliação Inicial:
A13: Itens de auditoria | B13: Aprovado | C13: Problema | D13: Correção Solicitada | E13: Data da Correção
A14: Os dados da UO como Razão Social e Endereço, constantes da aba DADOS DA EMPRESA, estão coerentes com o registro na Receita Federal? < Acessar o site a seguir para realizar a verificação: https://solucoes.receita.fazenda.gov.br/servicos/cnpjreva/cnpjreva_solicitacao.asp >
A15: A versão do modelo de referência e do método de avaliação estão corretas? < Verificar se são versões vigentes. >
A16: A aba PROJETOS/SERVIÇOS/ÁREAS foi preenchida e a seleção dos projetos/operações ou instâncias/áreas foi registrada? < Verificar se todos os itens pertinentes foram preenchidos e se entre os projetos/operações ou instâncias/áreas listados a seleção foi realizada e está registrada. Não cabe ao auditor solicitar registro de novas instâncias a não ser que não esteja registrado o número mínimo para o nível pretendido. >
A17: A aba PLANO está consistente com os projetos/operações ou instâncias/áreas selecionados? < Deve-se verificar a consistência apenas e nada além disso. >
A18: Exclusões de processos, na aba PLANO, estão documentadas? < Verificar se as exclusões possíveis de serem realizadas no modelo MPS pertinente foram registradas, caso pertinente. >
A19: As abas ACORDO_CONFIDENCIALIDADE, CRONOGRAMA INICIAL estão preenchidas para a avaliação inicial? < Verificar se as abas estão preenchidas. O Acordo de Confidencialidade pode ainda não estar assinado e em pdf. Verificar se as tarefas essenciais da avaliação inicial constam do cronograma. Caso não constem, deve-se registrar o problema, mas não deve ser solicitada alteração, pois a avaliação inicial já aconteceu. Ter em conta que treinamento pode não ser necessário. >
A20: A lista de envolvidos nos projetos/operações ou instâncias/áreas (aba EQUIPE) e processos organizacionais (aba EQUIPE_ORG) inclui todos os papéis pertinentes ao modelo e nível MPS avaliado e projetos/operações ou instâncias/áreas selecionados? < Verificar se as listas estão completas. Neste momento ainda não se precisar ter a decisão sobre os entrevistados. Pode-se ter, mas não é obrigatório. >
A21: O Acordo de Confidencialidade está com as assinaturas correspondentes e na pasta da avaliação? < Caso já esteja em pdf e assinado na pasta, verificar se está consistente com as informações da avaliação. Ter em conta que ainda não é obrigatório. >
A22: O Relatório de Ajustes para a Avaliação Final está coerente com as exigências do Modelo MPS avaliado? Todos os processos do nível e modelo avaliado estão registrados? < Verificar: (i) se os “requeridos” são pertinentes de acordo com as exigências do modelo no nível avaliado; (ii) se mesmo processos e CP do nível avaliado sem requeridos ou melhorias estão registrados com a informação de não terem requeridos ou melhorias. >
A23: O Relatório de Ajustes para a Avaliação Final em pdf e com a assinatura do avaliador líder está disponível na pasta da avaliação? < Verificar se foi incluída na pasta da avaliação uma versão do Relatório de Ajustes em pdf e assinada pelo avaliador líder. >
A24: As decisões expressas no Relatório de Avaliação Inicial enviado estão adequadas? Caso pertinente, foi enviada solicitação de avaliação final sem o avaliador adjunto? < (i) Verificar se o Relatório enviado por e-mail está adequado. Caso contrário, solicitar ajuste e envio de outro e-mail; (ii) caso pertinente, verificar a justificativa de exclusão do avaliador adjunto na avaliação final; (iii) caso tenha havido alteração de patrocinador, verificar se a alteração foi registrada na Planilha de Avaliação. >
A25: O logo da empresa se encontra na pasta da avaliação? < Verificar se o logo da empresa já está na pasta da avaliação e, caso não esteja, solicitar que seja colocado até a conclusão da avaliação final. O logo ainda não estar na pasta não impede a auditoria de dar o resultado APROVADO. >
... A28: AUDITORIA DA AVALIAÇÃO FINAL
A29: Apreciação sobre o resultado da avaliação MPS na empresa: | C29: Justificativa:
A30: Parecer Final sobre a Avaliação Final:
A32: Itens de auditoria | B32: Aprovado | C32: Problema | D32: Correção Solicitada | E32: Data da Correção
A33: Os projetos/operações ou instâncias/áreas incluídos para ajustes estão listadas nas abas PROJETOS/SERVIÇOS/ÁREAS e PLANO? < Verificar se os projetos/operações ou instâncias/áreas para evidenciar os ajustes para a avaliação final foram incluídos nas abas PROJETOS/SERVIÇOS/ÁREAS e PLANO. >
A34: A lista de envolvidos nos projetos/operações ou instâncias/áreas (aba EQUIPE) e processos organizacionais (aba EQUIPE_ORG) inclui todos os papéis pertinentes ao nível MPS avaliado e nos projetos/operações ou instâncias/áreas selecionados (incluindo os necessários para os ajustes) e a seleção dos entrevistados foi registrada nestas abas? < Verificar se as listas estão completas e se estão selecionados os entrevistados. >
A35: Foi elaborado o cronograma da avaliação final com as atividades pertinentes e indicação dos participantes nas entrevistas? < Verificar: (i) se as atividades obrigatórias na avaliação final foram planejadas; (ii) se as entrevistas foram registradas com os processos considerados e os participantes em cada uma. >
A36: Se houve alteração de patrocinador ou composição da equipe, todas as informações estão corretamente registradas na aba RESULTADO_INICIAL? < (i) Verificar se o Relatório enviado por e-mail está atualizado. Caso contrário, solicitar ajuste e envio de outro e-mail; (ii) caso pertinente, verificar se foi enviada, após a auditoria da avaliação inicial, a justificativa de exclusão do avaliador adjunto na avaliação final; (iii) caso tenha havido alteração de patrocinador, verificar se a alteração foi registrada na Planilha de Avaliação. Ter em conta que mesmo não participando da avaliação final, o avaliador adjunto não deve ser excluído da aba pertinente na Planilha de Avaliação. >
A37: Caso não tenha sido assinado na avaliação inicial, ou se houve alteração de patrocinador/composição de equipe, o Acordo de Confidencialidade (em pdf) está consistente com as informações da avaliação e está com as assinaturas adequadas na pasta de avaliação? < Ter em conta que a exclusão de um membro da equipe de avaliação na avaliação final não é razão para alteração do Acordo de Confidencialidade. >
A38: O Relatório de Ajustes para a Avaliação Final, na versão para avaliação final, está em pdf com a assinatura do avaliador líder e disponível na pasta da avaliação? Se não houver requerido o Relatório de Ajustes para a Avaliação Final não é necessário gerar outra versão do Relatório de Ajustes. < Ter em conta que quem preenche o Relatório de Ajustes entre a avaliação inicial e final é a empresa. Portanto, cabe ao avaliador líder apenas assinar e gerar o pdf. Não cabe ao avaliador líder completar ou alterar este documento. Portanto, o Relatório pode não estar correto ou completo. >
A39: O Resultado da Avaliação Final está preenchido corretamente na aba RESULTADO_FINAL, foi gerado o seu pdf com a assinatura do avaliador líder e está disponível na pasta da avaliação?
A40: A "Apresentação Resultado Final" da avaliação está correta e consistente com o Relatório de Ajustes? < Ter em conta que podem ter ocorrido alterações devido às entrevistas. Em caso de dúvida, esclarecer com o avaliador líder. >
A41: A "Apresentação Resultado Final" está assinada pelo avaliador líder e o pdf disponível na pasta da avaliação?
A42: A "Apresentação Resultado Final" está com formato adequado para ser enviado à empresa? < Verificar formatação do pdf etc.>
A43: A Declaração da Avaliação está consistente com o resultado da avaliação, está em pdf com a assinatura do avaliador líder e disponível na pasta da avaliação?
A44: Os feedbacks foram preenchidos? < Verificar se houve o recebimento da informação via SOFTEX, contendo resultados do patrocinador e da equipe avaliadora. Outros envolvidos são opcionais.>
... A48: Feedbacks relevantes para melhoria (transcrever os feedbacks sem identificar quem escreveu)

Sheet PARAMETROS
A2: Versões dos Modelos MPS | D2: Níveis MPS | E2: Taxa SOFTEX - Não Associado | F2: Taxa SOFTEX - Associado | H2: Variações de "Não se aplica"
A3: MPS-SW Versão 2024 | D3: A - Em Otimização | E3: 8838 | F3: 8078 | H3: NA
A4: MPS-SV Versão 2024 | D4: B - Gerenciado Quantitativamente | E4: 7791 | F4: 7121 | H4: N/A
A5: MPS-RH Versão 2016 | D5: C - Definido | E5: 6861 | F5: 6271 | H5: Não se aplica
D6: D - Largamente Definido | E6: 5989 | F6: 5474 | H6: -
D7: E - Parcialmente Definido | E7: 5059 | F7: 4624
D8: F - Gerenciado | E8: 4245 | F8: 3880
D9: G - Parcialmente Gerenciado | E9: 3372 | F9: 3082
A11: Versões do Guia de Avaliação | D11: Parâmetros das abas que mudam em relação a SW, SV e RH
A12: MA-MPS (Guia de Avaliação:2024) | D12: Modelo | E12: Processos sendo avaliados | F12: Instâncias sendo avaliadas | G12: Referência Instâncias | H12: Gestor Instâncias | I12: Status Instâncias | J12: Instância aba Equipe | K12: Papel aba Equipe | L12: Col. Seleção | M12: Col. Instância | N12: Col. Gerente | O12: Col. Núm. Partic. | P12: Col. Situação
D13: SW | E13: Software | F13: Projetos | G13: Sprint ou Fase | H13: Gerente do Projeto | I13: Status | J13: Projeto | K13: Papel no projeto | L13: M | M13: A | N13: H | O13: G | P13: K
D14: SV | E14: Serviços | F14: Serviços | G14: Referência da Operação/Instância | H14: Gerente da Operação/Instância | I14: Status | J14: Operação/Instância | K14: Papel na operação/instância | L14: K | M14: A | N14: D | O14: F | P14: I
D15: RH | E15: Recursos Humanos | F15: Áreas | G15: - | H15: Gerente da Área | I15: - | J15: Área | K15: Papel na área | L15: F | M15: A | N15: E | O15: D
D17: Parâmetros aba Projetos | G17: Parâmetros aba Serviços | I17: Parâmetros abas Projetos / Serviços
A18: Formato avaliação | D18: Tipo de projeto | E18: Cliente | F18: Fase em que se encontra | G18: Cliente da Operação / Instância | H18: Fase em que se encontra | I18: Importância para a organização | J18: Seleção para avaliação
A19: Remoto | D19: Evolução Produto | E19: Interno | F19: Contratação | G19: Interno | H19: Contratação | I19: Baixa | J19: Sim
A20: Presencial | D20: Manutenção | E20: Externo | F20: Planejamento | G20: Externo | H20: Planejamento | I20: Média | J20: Não
D21: Desenvolvimento | F21: Pesquisa e MVP | H21: Execução | I21: Alta
A22: Tipo Curso Introdução | F22: Análise/projeto | H22: Execução Contínua
A23: SW | F23: Construção | H23: Parado
A24: SV | F24: Teste | H24: Concluído
A25: RH | F25: Parado
F26: Concluído
A27: Faixa de Receita Operacional
A28: Microempresa (Menor ou igual a R$ 2,4 milhões)
A29: Pequena empresa (Maior que R$ 2,4 milhões e menor ou igual a R$ 16 milhões) | D29: Seleção Entrevista | F29: Parâmetros aba Auditoria
A30: Média empresa (Maior que R$ 16 milhões e menor ou igual a R$ 90 milhões) | D30: Sim | F30: Resultado Auditoria | G30: Parecer Final Auditoria | H30: Resultado de Item de Auditoria
A31: Média-grande empresa (Maior que R$ 90 milhões e menor ou igual a R$ 300 milhões) | D31: Não | F31: Não há dúvidas | G31: Aprovado | H31: Sim
A32: Grande empresa (Maior que R$ 300 milhões) | F32: Há dúvidas | G32: Não aprovado | H32: Não
H33: Não se aplica
A34: Porte Empresa
A35: Microempresa (Até 9)
A36: Pequena empresa (de 10 a 49)
A37: Média empresa (de 50 a 99) | D37: Resultado da Avaliação Inicial
A38: Grande empresa (Mais que 100) | D38: Nível para a avaliação final
D39: Marcar a avaliação final para
A40: Associação Agente SOFTEX | D40: Dispensa do adjunto na avaliação final
A41: Sim | D41: Alterar a equipe de avaliação
A42: Não | D42: Alterar o patrocinador
D43: Alterar o coordenador local
...

Sheet Controle Versão
A1: Controle de Alterações - Kit do avaliador
A2: Data | B2: Documento | C2: Modificações
A3: 46021 | B3: Planilha de Avaliação (DECLARACAO_AVALIACAO) | C3: Ajuste de problema que fazia com que "processos de software" fossem mencionados na declaração de avaliação de serviços (MPS-SV) e gestão de pessoas (MPS-RH). Apesar disso, o nome, sigla e versão dos modelos eram identificados corretamente.
A4: 45686 | B4: Planilha de Avaliação (ACORDO_CONFIDENCIALIDADE, DECLARACAO_AVALIACAO) | C4: Os campos para assinaturas dos representantes da SOFTEX nestes documentos passam a mencionar apenas 'Gestor MPSBR Softex'.
A5: 45686 | B5: Planilha de Avaliação (ACORDO_CONFIDENCIALIDADE, DECLARACAO_AVALIACAO, RESULTADO_FINAL) | C5: Inclusão de mensagem ao final dos documentos informando que devem ser assinados eletronicamentes em plataforma com certificado digital ICP.
A6: 45686 | B6: Planilha de Avaliação, Relatório de Ajustes | C6: Ajuste no nome do processo Gerência de Configuração para avaliações do MPS-SV (estava com nome antigo, Gerência de Configuração de Serviços).
A7: 45686 | B7: Planilha de Avaliação (RESULTADO_INICIAL) | C7: Ajuste da abreviatura de 'atenciosamente' no texto sugerido para e-mail referente ao resultado inicial da avaliação inicial.
A8: 45686 | B8: Apresentação Resultado Final MPS-SV 2024 | C8: Ajustes nos resultados esperados de Gerência do Ciclo de Vida do Serviço com eliminação de repetição do resultado GVC 7.
A9: 45686 | B9: Kit de Avaliação (Versão 2023) | C9: Exclusão do Kit de Avaliação para as versões 2023 dos Guias MPS-SV e MPS-SW.
A10: 45469 | B10: Apresentação Resultado Final (MPS-SW:2024) | C10: Ajuste no slide que apresenta os resultados esperados de Gerência Organizacional de Software. Ajuste do nome do processo Gerência Organizacional de Software nos slides que consolidam o resultado da avaliação.
A11: 45444 | B11: Planilha de Avaliação | C11: Adequação às versões 2024 dos modelos MPS-SW e MPS-SV e do Método de Avaliação. Atualização dos nomes e resultados esperados dos processos dos modelos MPS-SW:2024 e MPS-SV:2024. Atualização da versão do Método de Avaliação (MA-MPS:2024).
A12: 45444 | B12: Apresentação Resultado Final (MPS-SW:2024, MPS-SV:2024) | C12: Adequação às versões 2024 dos modelos MPS-SW e MPS-SV. Atualização dos nomes e resultados esperados dos processos dos modelos MPS-SW:2024 e MPS-SV:2024.
A13: 45444 | B13: Reunião de Abertura (MPS-SW:2024, MPS-SV:2024) | C13: Adequação às versões 2024 dos modelos MPS-SW e MPS-SV. Atualização dos nomes dos processos dos modelos MPS-SW:2024 e MPS-SV:2024.
A14: 45444 | B14: Treinamento Avaliação Inicial MPS 2024 | C14: Atualização da versão do Método de Avaliação na capa.
... A62: 44986 | B62: Planilha de Avaliação (Geral) | C62: Ajustes diversos em fórmulas e referências cruzadas.
